2025-07-18T20:12:27.22661974Z 2025-07-18 20:12:27,223 - knowledge_base - INFO - Added document: core_003 - Position in Poker
2025-07-18T20:12:27.22662237Z 2025-07-18 20:12:27,223 - knowledge_base - INFO - Added document: core_004 - Bankroll Management
2025-07-18T20:12:27.22662476Z 2025-07-18 20:12:27,223 - knowledge_base - INFO - Added document: core_005 - Reading Opponents and Tells
2025-07-18T20:12:27.22662691Z 2025-07-18 20:12:27,223 - knowledge_base - INFO - Initialized knowledge base with 5 core documents
2025-07-18T20:12:27.22662922Z 2025-07-18 20:12:27,225 - vector_store - INFO - Initialized vector database at /tmp/vector_store.db
2025-07-18T20:12:27.22664581Z 2025-07-18 20:12:27,226 - vector_store - INFO - Loaded 5 vectors from database
2025-07-18T20:12:27.227027077Z 2025-07-18 20:12:27,226 - vector_store - INFO - Rebuilding vector index...
2025-07-18T20:12:27.241828498Z 2025-07-18 20:12:27,241 - embedding_service - INFO - Fitted TF-IDF vectorizer on 5 documents
2025-07-18T20:12:27.303555287Z 2025-07-18 20:12:27,302 - vector_store - INFO - Rebuilt vector index with 5 documents
2025-07-18T20:12:27.303567388Z 2025-07-18 20:12:27,302 - __main__ - INFO - Initialized vector store with 5 documents
2025-07-18T20:12:27.303570738Z 2025-07-18 20:12:27,303 - vector_store - INFO - Rebuilding vector index...
2025-07-18T20:12:27.311860375Z 2025-07-18 20:12:27,311 - embedding_service - INFO - Fitted TF-IDF vectorizer on 5 documents
2025-07-18T20:12:27.3448638Z 2025-07-18 20:12:27,344 - vector_store - INFO - Rebuilt vector index with 5 documents
2025-07-18T20:12:27.344877291Z 2025-07-18 20:12:27,344 - agent.retrieval_agent - INFO - Initialized vector store with 5 documents
2025-07-18T20:12:27.344911941Z 2025-07-18 20:12:27,344 - orchestrator - INFO - Registered agent Knowledge Retrieval Agent with capabilities: ['retrieve_knowledge', 'add_knowledge', 'update_knowledge', 'search_knowledge']
2025-07-18T20:12:27.344947562Z 2025-07-18 20:12:27,344 - orchestrator - INFO - Defined workflow 'rag_enhanced_hand_analysis': retrieval_agent -> hand_analyzer -> coach
2025-07-18T20:12:27.345000263Z 2025-07-18 20:12:27,344 - orchestrator - INFO - Defined workflow 'rag_enhanced_coaching': retrieval_agent -> coach
2025-07-18T20:12:27.345028223Z 2025-07-18 20:12:27,344 - orchestrator - INFO - Defined workflow 'rag_enhanced_learning': retrieval_agent -> learning_path
2025-07-18T20:12:27.345060524Z 2025-07-18 20:12:27,345 - orchestrator - INFO - Defined workflow 'rag_enhanced_community': retrieval_agent -> community
2025-07-18T20:12:27.345200757Z 2025-07-18 20:12:27,345 - knowledge_source_manager - INFO - Registered knowledge source: Poker Strategy Database
2025-07-18T20:12:27.345440921Z 2025-07-18 20:12:27,345 - knowledge_source_manager - INFO - Registered knowledge source: Hand History Database
2025-07-18T20:12:27.345449771Z 2025-07-18 20:12:27,345 - knowledge_source_manager - INFO - Registered knowledge source: Community Content
2025-07-18T20:12:27.345452531Z 2025-07-18 20:12:27,345 - knowledge_source_manager - INFO - Registered knowledge source: Learning Materials
2025-07-18T20:12:27.345487662Z 2025-07-18 20:12:27,345 - orchestrator - INFO - Registered agent RAG-Enhanced AI Poker Coach with capabilities: ['coaching_request', 'explain_concept', 'analyze_hand', 'general_question', 'rag_enhanced_responses']
2025-07-18T20:12:27.359467157Z Traceback (most recent call last):
2025-07-18T20:12:27.359555249Z   File "/usr/local/lib/python3.11/site-packages/sqlalchemy/engine/base.py", line 145, in __init__
2025-07-18T20:12:27.359727192Z     self._dbapi_connection = engine.raw_connection()
2025-07-18T20:12:27.359904625Z                              ^^^^^^^^^^^^^^^^^^^^^^^
2025-07-18T20:12:27.359941096Z   File "/usr/local/lib/python3.11/site-packages/sqlalchemy/engine/base.py", line 3297, in raw_connection
2025-07-18T20:12:27.360422505Z     return self.pool.connect()
2025-07-18T20:12:27.360456266Z            ^^^^^^^^^^^^^^^^^^^
2025-07-18T20:12:27.360460866Z   File "/usr/local/lib/python3.11/site-packages/sqlalchemy/pool/base.py", line 449, in connect
2025-07-18T20:12:27.3606882Z     return _ConnectionFairy._checkout(self)
2025-07-18T20:12:27.36069328Z            ^^^^^^^^^^^^^^^^^^^^^^^^^^^^^^^^
2025-07-18T20:12:27.36069698Z   File "/usr/local/lib/python3.11/site-packages/sqlalchemy/pool/base.py", line 1264, in _checkout
2025-07-18T20:12:27.361009166Z     fairy = _ConnectionRecord.checkout(pool)
2025-07-18T20:12:27.361014636Z             ^^^^^^^^^^^^^^^^^^^^^^^^^^^^^^^^
2025-07-18T20:12:27.361017936Z   File "/usr/local/lib/python3.11/site-packages/sqlalchemy/pool/base.py", line 713, in checkout
2025-07-18T20:12:27.36123733Z     rec = pool._do_get()
2025-07-18T20:12:27.36124319Z           ^^^^^^^^^^^^^^
2025-07-18T20:12:27.361246661Z   File "/usr/local/lib/python3.11/site-packages/sqlalchemy/pool/impl.py", line 179, in _do_get
2025-07-18T20:12:27.361433564Z     with util.safe_reraise():
2025-07-18T20:12:27.361452774Z   File "/usr/local/lib/python3.11/site-packages/sqlalchemy/util/langhelpers.py", line 224, in __exit__
2025-07-18T20:12:27.361571827Z     raise exc_value.with_traceback(exc_tb)
2025-07-18T20:12:27.36173619Z   File "/usr/local/lib/python3.11/site-packages/sqlalchemy/pool/impl.py", line 177, in _do_get
2025-07-18T20:12:27.361842112Z     return self._create_connection()
2025-07-18T20:12:27.361912283Z            ^^^^^^^^^^^^^^^^^^^^^^^^^
2025-07-18T20:12:27.362475464Z   File "/usr/local/lib/python3.11/site-packages/sqlalchemy/pool/base.py", line 390, in _create_connection
2025-07-18T20:12:27.362485464Z     return _ConnectionRecord(self)
2025-07-18T20:12:27.362488614Z            ^^^^^^^^^^^^^^^^^^^^^^^
2025-07-18T20:12:27.362491764Z   File "/usr/local/lib/python3.11/site-packages/sqlalchemy/pool/base.py", line 675, in __init__
2025-07-18T20:12:27.362495044Z     self.__connect()
2025-07-18T20:12:27.362497794Z   File "/usr/local/lib/python3.11/site-packages/sqlalchemy/pool/base.py", line 901, in __connect
2025-07-18T20:12:27.362501134Z     with util.safe_reraise():
2025-07-18T20:12:27.362503774Z   File "/usr/local/lib/python3.11/site-packages/sqlalchemy/util/langhelpers.py", line 224, in __exit__
2025-07-18T20:12:27.362597106Z     raise exc_value.with_traceback(exc_tb)
2025-07-18T20:12:27.362664417Z   File "/usr/local/lib/python3.11/site-packages/sqlalchemy/pool/base.py", line 897, in __connect
2025-07-18T20:12:27.362893252Z     self.dbapi_connection = connection = pool._invoke_creator(self)
2025-07-18T20:12:27.362944483Z                                          ^^^^^^^^^^^^^^^^^^^^^^^^^^
2025-07-18T20:12:27.362950553Z   File "/usr/local/lib/python3.11/site-packages/sqlalchemy/engine/create.py", line 646, in connect
2025-07-18T20:12:27.363156467Z     return dialect.connect(*cargs, **cparams)
2025-07-18T20:12:27.363302Z            ^^^^^^^^^^^^^^^^^^^^^^^^^^^^^^^^^^
2025-07-18T20:12:27.36330912Z   File "/usr/local/lib/python3.11/site-packages/sqlalchemy/engine/default.py", line 625, in connect
2025-07-18T20:12:27.363508524Z     return self.loaded_dbapi.connect(*cargs, **cparams)  # type: ignore[no-any-return]  # NOQA: E501
2025-07-18T20:12:27.363758618Z            ^^^^^^^^^^^^^^^^^^^^^^^^^^^^^^^^^^^^^^^^^^^^
2025-07-18T20:12:27.363764468Z   File "/usr/local/lib/python3.11/site-packages/psycopg2/__init__.py", line 122, in connect
2025-07-18T20:12:27.363771318Z     conn = _connect(dsn, connection_factory=connection_factory, **kwasync)
2025-07-18T20:12:27.363908001Z            ^^^^^^^^^^^^^^^^^^^^^^^^^^^^^^^^^^^^^^^^^^^^^^^^^^^^^^^^^^^^^^^
2025-07-18T20:12:27.363986633Z psycopg2.OperationalError: connection to server at "db.oouwsohqgsgsnougdvgh.supabase.co" (2600:1f1c:f9:4d0d:85ef:77cd:e615:40c8), port 5432 failed: Network is unreachable
2025-07-18T20:12:27.363990333Z 	Is the server running on that host and accepting TCP/IP connections?
2025-07-18T20:12:27.363992613Z 
2025-07-18T20:12:27.363994643Z 
2025-07-18T20:12:27.363996903Z The above exception was the direct cause of the following exception:
2025-07-18T20:12:27.363999173Z 
2025-07-18T20:12:27.364001603Z Traceback (most recent call last):
2025-07-18T20:12:27.364007283Z   File "/app/Agentic_Rag/main_rag_integrated.py", line 222, in <module>
2025-07-18T20:12:27.364140185Z     main()
2025-07-18T20:12:27.364144486Z   File "/app/Agentic_Rag/main_rag_integrated.py", line 196, in main
2025-07-18T20:12:27.364803218Z     app, socketio = create_app()
2025-07-18T20:12:27.364811918Z                     ^^^^^^^^^^^^
2025-07-18T20:12:27.364814918Z   File "/app/Agentic_Rag/main_rag_integrated.py", line 108, in create_app
2025-07-18T20:12:27.364848739Z     db.create_all()
2025-07-18T20:12:27.364852509Z   File "/usr/local/lib/python3.11/site-packages/flask_sqlalchemy/extension.py", line 900, in create_all
2025-07-18T20:12:27.364855029Z     self._call_for_binds(bind_key, "create_all")
2025-07-18T20:12:27.364857409Z   File "/usr/local/lib/python3.11/site-packages/flask_sqlalchemy/extension.py", line 881, in _call_for_binds
2025-07-18T20:12:27.364869899Z     getattr(metadata, op_name)(bind=engine)
2025-07-18T20:12:27.364936331Z   File "/usr/local/lib/python3.11/site-packages/sqlalchemy/sql/schema.py", line 5924, in create_all
2025-07-18T20:12:27.366786355Z     bind._run_ddl_visitor(
2025-07-18T20:12:27.366795656Z   File "/usr/local/lib/python3.11/site-packages/sqlalchemy/engine/base.py", line 3247, in _run_ddl_visitor
2025-07-18T20:12:27.36702383Z     with self.begin() as conn:
2025-07-18T20:12:27.3670289Z   File "/usr/local/lib/python3.11/contextlib.py", line 137, in __enter__
2025-07-18T20:12:27.367112382Z     return next(self.gen)
2025-07-18T20:12:27.367231824Z            ^^^^^^^^^^^^^^
2025-07-18T20:12:27.367237304Z   File "/usr/local/lib/python3.11/site-packages/sqlalchemy/engine/base.py", line 3237, in begin
2025-07-18T20:12:27.367825535Z     with self.connect() as conn:
2025-07-18T20:12:27.367903977Z          ^^^^^^^^^^^^^^
2025-07-18T20:12:27.367909167Z   File "/usr/local/lib/python3.11/site-packages/sqlalchemy/engine/base.py", line 3273, in connect
2025-07-18T20:12:27.368349715Z     return self._connection_cls(self)
2025-07-18T20:12:27.368499378Z            ^^^^^^^^^^^^^^^^^^^^^^^^^^
2025-07-18T20:12:27.368507838Z   File "/usr/local/lib/python3.11/site-packages/sqlalchemy/engine/base.py", line 147, in __init__
2025-07-18T20:12:27.368658121Z     Connection._handle_dbapi_exception_noconnection(
2025-07-18T20:12:27.368664031Z   File "/usr/local/lib/python3.11/site-packages/sqlalchemy/engine/base.py", line 2436, in _handle_dbapi_exception_noconnection
2025-07-18T20:12:27.369012828Z     raise sqlalchemy_exception.with_traceback(exc_info[2]) from e
2025-07-18T20:12:27.369018408Z   File "/usr/local/lib/python3.11/site-packages/sqlalchemy/engine/base.py", line 145, in __init__
2025-07-18T20:12:27.369241192Z     self._dbapi_connection = engine.raw_connection()
2025-07-18T20:12:27.369256153Z                              ^^^^^^^^^^^^^^^^^^^^^^^
2025-07-18T20:12:27.369259422Z   File "/usr/local/lib/python3.11/site-packages/sqlalchemy/engine/base.py", line 3297, in raw_connection
2025-07-18T20:12:27.369734622Z     return self.pool.connect()
2025-07-18T20:12:27.369743092Z            ^^^^^^^^^^^^^^^^^^^
2025-07-18T20:12:27.369746152Z   File "/usr/local/lib/python3.11/site-packages/sqlalchemy/pool/base.py", line 449, in connect
2025-07-18T20:12:27.369906495Z     return _ConnectionFairy._checkout(self)
2025-07-18T20:12:27.369996576Z            ^^^^^^^^^^^^^^^^^^^^^^^^^^^^^^^^
2025-07-18T20:12:27.370001387Z   File "/usr/local/lib/python3.11/site-packages/sqlalchemy/pool/base.py", line 1264, in _checkout
2025-07-18T20:12:27.370301902Z     fairy = _ConnectionRecord.checkout(pool)
2025-07-18T20:12:27.370306932Z             ^^^^^^^^^^^^^^^^^^^^^^^^^^^^^^^^
2025-07-18T20:12:27.370369614Z   File "/usr/local/lib/python3.11/site-packages/sqlalchemy/pool/base.py", line 713, in checkout
2025-07-18T20:12:27.370623088Z     rec = pool._do_get()
2025-07-18T20:12:27.370659979Z           ^^^^^^^^^^^^^^
2025-07-18T20:12:27.370663179Z   File "/usr/local/lib/python3.11/site-packages/sqlalchemy/pool/impl.py", line 179, in _do_get
2025-07-18T20:12:27.370752841Z     with util.safe_reraise():
2025-07-18T20:12:27.370757331Z   File "/usr/local/lib/python3.11/site-packages/sqlalchemy/util/langhelpers.py", line 224, in __exit__
2025-07-18T20:12:27.370802562Z     raise exc_value.with_traceback(exc_tb)
2025-07-18T20:12:27.370931724Z   File "/usr/local/lib/python3.11/site-packages/sqlalchemy/pool/impl.py", line 177, in _do_get
2025-07-18T20:12:27.371075807Z     return self._create_connection()
2025-07-18T20:12:27.371080477Z            ^^^^^^^^^^^^^^^^^^^^^^^^^
2025-07-18T20:12:27.371083627Z   File "/usr/local/lib/python3.11/site-packages/sqlalchemy/pool/base.py", line 390, in _create_connection
2025-07-18T20:12:27.371291081Z     return _ConnectionRecord(self)
2025-07-18T20:12:27.371296161Z            ^^^^^^^^^^^^^^^^^^^^^^^
2025-07-18T20:12:27.371299271Z   File "/usr/local/lib/python3.11/site-packages/sqlalchemy/pool/base.py", line 675, in __init__
2025-07-18T20:12:27.371495775Z     self.__connect()
2025-07-18T20:12:27.372543425Z   File "/usr/local/lib/python3.11/site-packages/sqlalchemy/pool/base.py", line 901, in __connect
2025-07-18T20:12:27.372551715Z     with util.safe_reraise():
2025-07-18T20:12:27.372554565Z   File "/usr/local/lib/python3.11/site-packages/sqlalchemy/util/langhelpers.py", line 224, in __exit__
2025-07-18T20:12:27.372559845Z     raise exc_value.with_traceback(exc_tb)
2025-07-18T20:12:27.372562325Z   File "/usr/local/lib/python3.11/site-packages/sqlalchemy/pool/base.py", line 897, in __connect
2025-07-18T20:12:27.372564965Z     self.dbapi_connection = connection = pool._invoke_creator(self)
2025-07-18T20:12:27.372567515Z                                          ^^^^^^^^^^^^^^^^^^^^^^^^^^
2025-07-18T20:12:27.372569975Z   File "/usr/local/lib/python3.11/site-packages/sqlalchemy/engine/create.py", line 646, in connect
2025-07-18T20:12:27.372572875Z     return dialect.connect(*cargs, **cparams)
2025-07-18T20:12:27.372575995Z            ^^^^^^^^^^^^^^^^^^^^^^^^^^^^^^^^^^
2025-07-18T20:12:27.372578835Z   File "/usr/local/lib/python3.11/site-packages/sqlalchemy/engine/default.py", line 625, in connect
2025-07-18T20:12:27.372581656Z     return self.loaded_dbapi.connect(*cargs, **cparams)  # type: ignore[no-any-return]  # NOQA: E501
2025-07-18T20:12:27.372584685Z            ^^^^^^^^^^^^^^^^^^^^^^^^^^^^^^^^^^^^^^^^^^^^
2025-07-18T20:12:27.372587345Z   File "/usr/local/lib/python3.11/site-packages/psycopg2/__init__.py", line 122, in connect
2025-07-18T20:12:27.372609676Z     conn = _connect(dsn, connection_factory=connection_factory, **kwasync)
2025-07-18T20:12:27.372727868Z            ^^^^^^^^^^^^^^^^^^^^^^^^^^^^^^^^^^^^^^^^^^^^^^^^^^^^^^^^^^^^^^^
2025-07-18T20:12:27.372733298Z sqlalchemy.exc.OperationalError: (psycopg2.OperationalError) connection to server at "db.oouwsohqgsgsnougdvgh.supabase.co" (2600:1f1c:f9:4d0d:85ef:77cd:e615:40c8), port 5432 failed: Network is unreachable
2025-07-18T20:12:27.372736058Z 	Is the server running on that host and accepting TCP/IP connections?
2025-07-18T20:12:27.372738118Z 
2025-07-18T20:12:27.372740648Z (Background on this error at: https://sqlalche.me/e/20/e3q8)